<sdf version='1.7'>
  <model name='two_wheeled_robot_mine'>
    <link name='base_link'>
      <inertial>
        <pose>0.075 0 0.053571 0 -0 0</pose>
        <mass>0.7</mass>
        <inertia>
          <ixx>0.0306619</ixx>
          <ixy>0</ixy>
          <ixz>-0.007875</ixz>
          <iyy>0.0495369</iyy>
          <iyz>0</iyz>
          <izz>0.0232333</izz>
        </inertia>
      </inertial>
      <collision name='base_link_collision'>
        <pose>0 0 0.2 0 -0 0</pose>
        <geometry>
          <box>
            <size>0.5 0.5 0.2</size>
          </box>
        </geometry>
        <surface>
          <contact>
            <ode/>
          </contact>
          <friction>
            <ode/>
          </friction>
        </surface>
      </collision>
      <collision name='base_link_fixed_joint_lump__front_sphere_collision_1'>
        <pose>0.225 0 0.075 0 -0 0</pose>
        <geometry>
          <sphere>
            <radius>0.025</radius>
          </sphere>
        </geometry>
      </collision>
      <collision name='base_link_fixed_joint_lump__lidar_link_collision_2'>
        <pose>0.3 0 0.3 0 -0 0</pose>
        <geometry>
          <cylinder>
            <length>0.05</length>
            <radius>0.0508</radius>
          </cylinder>
        </geometry>
        <surface>
          <contact>
            <ode/>
          </contact>
          <friction>
            <ode/>
          </friction>
        </surface>
      </collision>
      <visual name='base_link_visual'>
        <pose>0 0 0.2 0 -0 0</pose>
        <geometry>
          <box>
            <size>0.5 0.5 0.2</size>
          </box>
        </geometry>
        <material>
          <script>
            <name>Gazebo/Red</name>
            <uri>file://media/materials/scripts/gazebo.material</uri>
          </script>
        </material>
      </visual>
      <visual name='base_link_fixed_joint_lump__front_sphere_visual_1'>
        <pose>0.225 0 0.075 0 -0 0</pose>
        <geometry>
          <sphere>
            <radius>0.025</radius>
          </sphere>
        </geometry>
      </visual>
      <visual name='base_link_fixed_joint_lump__lidar_link_visual_2'>
        <pose>0.3 0 0.3 0 -0 0</pose>
        <geometry>
          <cylinder>
            <length>0.05</length>
            <radius>0.0508</radius>
          </cylinder>
        </geometry>
      </visual>
      <sensor name='laser' type='ray'>
        <ray>
          <scan>
            <horizontal>
              <samples>181</samples>
              <resolution>1</resolution>
              <min_angle>-1.5708</min_angle>
              <max_angle>1.5708</max_angle>
            </horizontal>
          </scan>
          <range>
            <min>0.08</min>
            <max>10</max>
            <resolution>0.05</resolution>
          </range>
        </ray>
        <always_on>1</always_on>
        <update_rate>10</update_rate>
        <visualize>1</visualize>
        <plugin name='laser' filename='libgazebo_ros_ray_sensor.so'>
          <ros>
            <namespace>/demo</namespace>
            <argument>--ros-args --remap ~/out:=scan</argument>
          </ros>
          <output_type>sensor_msgs/LaserScan</output_type>
        </plugin>
        <pose>0.3 0 0.3 0 -0 0</pose>
      </sensor>
    </link>
    <joint name='drivewheel_l_joint' type='revolute'>
      <pose relative_to='base_link'>-0.2 -0.3 0.2 0 -0 0</pose>
      <parent>base_link</parent>
      <child>drivewheel_l_link</child>
      <axis>
        <xyz>0 1 0</xyz>
        <limit>
          <lower>-3.14159</lower>
          <upper>3.14159</upper>
          <effort>30</effort>
          <velocity>5</velocity>
        </limit>
        <dynamics>
          <spring_reference>0</spring_reference>
          <spring_stiffness>0</spring_stiffness>
        </dynamics>
      </axis>
    </joint>
    <link name='drivewheel_l_link'>
      <pose relative_to='drivewheel_l_joint'>0 0 0 0 -0 0</pose>
      <inertial>
        <pose>0 0 0 1.5708 -0 0</pose>
        <mass>0.1</mass>
        <inertia>
          <ixx>0.000583333</ixx>
          <ixy>0</ixy>
          <ixz>0</ixz>
          <iyy>0.000583333</iyy>
          <iyz>0</iyz>
          <izz>0.001125</izz>
        </inertia>
      </inertial>
      <collision name='drivewheel_l_link_collision'>
        <pose>0 0 0 1.5708 -0 0</pose>
        <geometry>
          <cylinder>
            <length>0.05</length>
            <radius>0.15</radius>
          </cylinder>
        </geometry>
        <surface>
          <contact>
            <ode/>
          </contact>
          <friction>
            <ode/>
          </friction>
        </surface>
      </collision>
      <visual name='drivewheel_l_link_visual'>
        <pose>0 0 0 1.5708 -0 0</pose>
        <geometry>
          <cylinder>
            <length>0.05</length>
            <radius>0.15</radius>
          </cylinder>
        </geometry>
        <material>
          <script>
            <name>Gazebo/White</name>
            <uri>file://media/materials/scripts/gazebo.material</uri>
          </script>
        </material>
      </visual>
    </link>
    <joint name='drivewheel_r_joint' type='revolute'>
      <pose relative_to='base_link'>-0.2 0.3 0.2 0 -0 0</pose>
      <parent>base_link</parent>
      <child>drivewheel_r_link</child>
      <axis>
        <xyz>0 1 0</xyz>
        <limit>
          <lower>-3.14159</lower>
          <upper>3.14159</upper>
          <effort>30</effort>
          <velocity>5</velocity>
        </limit>
        <dynamics>
          <spring_reference>0</spring_reference>
          <spring_stiffness>0</spring_stiffness>
        </dynamics>
      </axis>
    </joint>
    <link name='drivewheel_r_link'>
      <pose relative_to='drivewheel_r_joint'>0 0 0 0 -0 0</pose>
      <inertial>
        <pose>0 0 0 1.5708 -0 0</pose>
        <mass>0.1</mass>
        <inertia>
          <ixx>0.000583333</ixx>
          <ixy>0</ixy>
          <ixz>0</ixz>
          <iyy>0.000583333</iyy>
          <iyz>0</iyz>
          <izz>0.001125</izz>
        </inertia>
      </inertial>
      <collision name='drivewheel_r_link_collision'>
        <pose>0 0 0 1.5708 -0 0</pose>
        <geometry>
          <cylinder>
            <length>0.05</length>
            <radius>0.15</radius>
          </cylinder>
        </geometry>
        <surface>
          <contact>
            <ode/>
          </contact>
          <friction>
            <ode/>
          </friction>
        </surface>
      </collision>
      <visual name='drivewheel_r_link_visual'>
        <pose>0 0 0 1.5708 -0 0</pose>
        <geometry>
          <cylinder>
            <length>0.05</length>
            <radius>0.15</radius>
          </cylinder>
        </geometry>
        <material>
          <script>
            <name>Gazebo/White</name>
            <uri>file://media/materials/scripts/gazebo.material</uri>
          </script>
        </material>
      </visual>
    </link>
    <static>0</static>
    <plugin name='diff_drive' filename='libgazebo_ros_diff_drive.so'>
      <ros>
        <namespace>/demo</namespace>
        <remapping>cmd_vel:=cmd_vel</remapping>
        <remapping>odom:=odom</remapping>
      </ros>
      <updata_rate>30</updata_rate>
      <left_joint>drivewheel_l_joint</left_joint>
      <right_joint>drivewheel_r_joint</right_joint>
      <wheel_separation>0.65</wheel_separation>
      <wheel_diameter>0.3</wheel_diameter>
      <max_wheel_torque>3</max_wheel_torque>
      <max_wheel_acceleration>1.0</max_wheel_acceleration>
      <publish_odom>1</publish_odom>
      <publish_odom_tf>1</publish_odom_tf>
      <publish_wheel_tf>1</publish_wheel_tf>
      <odometry_frame>odom</odometry_frame>
      <robot_base_frame>base_link</robot_base_frame>
    </plugin>
    <frame name='front_sphere_joint' attached_to='base_link'>
      <pose>0.225 0 0.075 0 -0 0</pose>
    </frame>
    <frame name='front_sphere' attached_to='front_sphere_joint'/>
    <frame name='imu_joint' attached_to='base_link'>
      <pose>0.1 0 0.1 0 -0 0</pose>
    </frame>
    <frame name='imu_link' attached_to='imu_joint'/>
    <frame name='lidar_joint' attached_to='base_link'>
      <pose>0.3 0 0.3 0 -0 0</pose>
    </frame>
    <frame name='lidar_link' attached_to='lidar_joint'/>
  </model>
</sdf>
